Workbook
Name _GoBack: 'NBCSP, PHN '!$L$5

Sheet TOC
B1: ABN 16 515 245 497 www.aihw.gov.au Australian Institute of Health and Welfare GPO Box 570, Canberra ACT 2601, Australia Email: screeninganalysismonitoring@aihw.gov.au
A4: Table of contents
A6: Cancer screening programs: quarterly data
A7: 14 July 2023
A9: National Bowel Cancer Screening Program (NBCSP)
A10: ='NBCSP, Trend'!A2 -> Table 1: Participation in the National Bowel Cancer Screening Program, by sex, people aged 50–74, 2007–2008 to 2020–2021
A11: ='NBCSP, State, Sex, Age group '!A2 -> Table 2: Participation in the National Bowel Cancer Screening Program, by state/territory, sex and 5-year age group, people aged 50–74, 2014–2015 to 2020–2021
A12: ='NBCSP, Reparticipation'!A2 -> Table 3: Reparticipation in the National Bowel Cancer Screening Program, by 5-year age group, people aged 50–74, 2015–2016 to 2020–2021
A13: ='NBCSP, PHN '!A2 -> Table 4: Participation in the National Bowel Cancer Screening Program, by Primary Health Network area, people aged 50–74, 2014–2015 to 2020–2021
A14: ='NBCSP, SA3 2016'!A2 -> Table 5a: Participation in the National Bowel Cancer Screening Program, by Statistical Area Level 3 (ASGS 2016), people aged 50–74, 2018–2019 to 2020–2021
A15: ='NBCSP, SA3 2011'!A2 -> Table 5b: Participation in the National Bowel Cancer Screening Program, by Statistical Area Level 3 (ASGS 2011), people aged 50–74, 2014–2015 to 2017–2018
A16: ='NBCSP, SA2 2016 '!A2 -> Table 6a: Participation in the National Bowel Cancer Screening Program by Statistical Area Level 2 (ASGS 2016), people aged 50–74, 2019-2020 to 2020–2021
A17: ='NBCSP, SA2 2011'!A2 -> Table 6b: Participation in the National Bowel Cancer Screening Program, by Statistical Area Level 2 (AGSG 2011), people aged 50–74, 2015–2016 to 2017–2018
A18: ='NBCSP, Activity-Invites-State-'!A2 -> Table 7: Number of screening invitations issued by the National Bowel Cancer Screening Program, by quarter, month, sex and state/territory, people aged 50–74, January 2014 to March 2023
A19: ='NBCSP, Activity-Kits-State'!A2 -> Table 8: Number of complete screening kits returned to the National Bowel Cancer Screening Program, by quarter, month, sex and state/territory, people aged 50–74, January 2014 to March 2023
A20: BreastScreen Australia
A21: ='BreastScreen, State, Age group'!A2 -> Table 9: Participation in BreastScreen Australia, by state/territory and 5-year age group, women aged 50–74, 2014–2015 to 2021–2022
A22: ='BreastScreen AS participation'!A2 -> Table 10: Age-standardised participation rates in BreastScreen Australia, by state/territory, women aged 50–69 and 50–74, 2014–2015 to 2021–2022
A23: ='BreastScreen, PHN'!A2 -> Table 11: Participation in BreastScreen Australia, by Primary Health Network area and 5-year age group, women aged 50–74, 2014–2015 to 2019-2020
A24: ='BreastScreen, SA3 2016'!A2 -> Table 12a: Participation in BreastScreen Australia, by Statistical Area Level 3 (ASGS 2016) and 5-year age group, women aged 50–74, 2016–2017 to 2019–2020
A25: ='BreastScreen, SA3 2011'!A2 -> Table 12b: Participation in BreastScreen Australia, by Statistical Area Level 3 (ASGS 2011) and 5-year age group, women aged 50–74, 2014–2015 to 2015–2016
A26: ='BreastScreen, Activity, 40-49'!A2 -> Table 13a: Number of screening mammograms performed through BreastScreen Australia, by quarter, month and state/territory, women aged 40–49, January 2014 to March 2023
A27: ='BreastScreen, Activity, 50-74'!A2 -> Table 13b: Number of screening mammograms performed through BreastScreen Australia, by quarter, month and state/territory, women aged 50–74, January 2014 to March 2023
A28: ='BreastScreen, Activity, 75+'!A2 -> Table 13c: Number of screening mammograms performed through BreastScreen Australia, by quarter, month and state/territory, women aged 75+, January 2014 to March 2023
A29: ='BreastScreen, Activity, 40+'!A2 -> Table 13d: Number of screening mammograms performed through BreastScreen Australia, by quarter, month and state/territory, women aged 40+, January 2014 to March 2023
A30: National Cervical Screening Program (NCSP)
A31: ='NCSP, State, Age group'!A2 -> Table 14a: Participation in the renewed National Cervical Screening Program, by state/territory and 5-year age group, people aged 25–74, 2018–2022
A32: ='NCSP State AS'!A2 -> Table 14b: Age-standardised participation rates for the renewed National Cervical Screening Program, by state/territory, people aged 25–74, 2018–2022
A33: ='Previous NCSP, State, Age group'!A2 -> Table 15a: Participation in the previous National Cervical Screening Program, by state/territory and 5-year age group, people aged 20–69, 2014–2015 to 2015–2016
A34: ='Previous NCSP, State AS'!A2 -> Table 15b: Age-standardised participation rates for the previous National Cervical Screening Program, by state/territory, people aged 20–69, 2014–2015 to 2015–2016
A35: ='NCSP, PHN'!A2 -> Table 16a: Participation in the National Cervical Screening Program, by Primary Health Network area and 5-year age group, people aged 25–74, 2018–2021
A36: ='Previous NCSP, PHN'!A2 -> Table 16b: Participation in the previous National Cervical Screening Program, by Primary Health Network area and 5-year age group, people aged 20–69, 2014–2015 to 2015–2016
A37: ='NCSP, SA3'!A2 -> Table 17a: Participation in the National Cervical Screening Program, by Statistical Area Level 3 (ASGS 2016) and 5-year age group, people aged 25–74, 2018–2021
A38: ='Previous NCSP, SA3'!A2 -> Table 17b: Participation in the previous National Cervical Screening Program, by Statistical Area Level 3 and 5-year age group, people aged 20–69, 2014–2015 to 2015–2016
A39: ='NCSP, Activity by State'!A2 -> Table 18: Number of primary screening tests performed through the National Cervical Screening Program, by quarter, month and state/territory, people aged 25–74, January 2018 to March 2023
A41: Sources:
A42: Australian Institute of Health and Welfare analysis of National Bowel Cancer Screening Program register data.
A43: Australian Institute of Health and Welfare analysis of BreastScreen data.
A44: Australian Institute of Health and Welfare analysis of National Cancer Screening Register data.
A45: Australian Institute of Health and Welfare analysis of state and territory cervical screening register data.

Sheet Abbreviations & Symbols
A2: Abbreviations
A3: ABS | B3: Australian Bureau of Statistics
A4: AIHW | B4: Australian Institute of Health and Welfare
A5: ASGS | B5: Australian Statistical Geography Standard
A6: DHAC | B6: Australian Department of Health and Aged Care
A7: HPV | B7: human papilloma virus
A8: NBCSP | B8: National Bowel Cancer Screening Program
A9: NCSP | B9: National Cervical Screening Program
A10: NCSR | B10: National Cancer Screening Register
A11: PHN | B11: Primary Health Network area
A12: RDE | B12: Raw Data Extract
A13: SA3 | B13: Statistical Areas Level 3
A14: SA2 | B14: Statistical Areas Level 2
A15: SA1 | B15: Statistical Areas Level 1
A17: Symbols
A19: n.a. | B19: not available, not applicable
A20: n.p. | B20: not published (due to small numbers, confidentiality and/or reliability concerns)
A21: . . | B21: no data/insufficient data

Sheet NBCSP, Trend
A1: Click to return to TOC
A2: Table 1: Participation in the National Bowel Cancer Screening Program, by sex, people aged 50–74, 2007–2008 to 2020–2021
A3: Sex | B3: 2007–2008 | C3: 2008–2009 | D3: 2009–2010 | E3: 2010–2011 | F3: 2011–2012 | G3: 2012–2013 | H3: 2013–2014 | I3: 2014–2015 | J3: 2015–2016 | K3: 2016–2017 | L3: 2017–2018 | M3: 2018–2019 | N3: 2019–2020 | O3: 2020–2021
A4: Males | B4: 40 | C4: 39.8 | D4: 37.9 | E4: 35.7 | F4: 34.1 | G4: 33.4 | H4: 34.7 | I4: 36.5 | J4: 39 | K4: 39.4 | L4: 40.2 | M4: 41.3 | N4: 41.9 | O4: 38.9
A5: Females | B5: 48.2 | C5: 47.5 | D5: 44.2 | E5: 41.6 | F5: 39.9 | G5: 38.8 | H5: 40.1 | I5: 41.2 | J5: 42.9 | K5: 43.2 | L5: 44.5 | M5: 45.6 | N5: 45.7 | O5: 42.8
A6: Persons | B6: 44 | C6: 43.6 | D6: 41 | E6: 38.6 | F6: 37 | G6: 36.1 | H6: 37.4 | I6: 38.9 | J6: 40.9 | K6: 41.3 | L6: 42.4 | M6: 43.5 | N6: 43.8 | O6: 40.9
A8: Notes
A9: 1. Biennial screening was fully rolled out in 2020 to people aged 50–74. For earlier periods, the specific ages invited within the 50–74 age range included 55 and 65 in 2007; 50, 55 and 65 in 2008 to 2013; 50, 55, 60 and 65 in 2014; 50, 55, 60, 65, 70 and 74 in 2015; 50, 55, 60, 64, 65, 70, 72 and 74 in 2016; 50, 54, 55, 58, 60, 64, 68, 70, 72 and 74 in 2017; and 50, 54, 58, 60, 62, 64, 66, 68, 70, 72 and 74 in 2018 and 50, 52, 54, 56, 58, 60, 62, 64, 66, 68, 70, 72 and 74 in 2019.
A10: 2. These results calculate participation rates using the new NBCSP performance indicator specifications. This indicator now measures a 2-year invitation period and also excludes those who opted off or suspended participation. Therefore, these results cannot be compared to rates reported prior to 2014. For further information see the NBCSP performance indicator documentation (https://www.aihw.gov.au/reports-data/health-welfare-services/cancer-screening/indicators).
A11: 3. Each 2-year period covers from 1 January in the first year to 31 December in the following year. For example, 2017–2018 covers 1 January 2017 to 31 December 2018 inclusive.
A12: 4. These data are sourced from a live database, which is updated over time, with later data supply likely to have a greater level of completeness. This means that the data in this report may differ from data sourced at a different time.
A14: Source: AIHW analysis of National Bowel Cancer Screening Program (Department of Human Services) register data and National Cancer Screening Register data (NCSR RDE 14/01/2023).

Sheet NBCSP, State, Sex, Age group 
A1: Click to return to TOC
A2: Table 2: Participation in the National Bowel Cancer Screening Program, by state/territory, sex and 5-year age group, people aged 50–74, 2014–2015 to 2020–2021
D3: 2014–2015 | H3: 2015–2016 | L3: 2016–2017 | P3: 2017–2018 | T3: 2018–2019 | X3: 2019–2020 | AB3: 2020–2021
A4: State/territory | B4: Sex | C4: Age group | D4: Participated | E4: Invited | F4: Participation (%) | H4: Participated | I4: Invited | J4: Participation (%) | L4: Participated | M4: Invited | N4: Participation (%) | P4: Participated | Q4: Invited | R4: Participation (%) | T4: Participated | U4: Invited | V4: Participation (%) | X4: Participated | Y4: Invited | Z4: Participation (%) | AB4: Participated | AC4: Invited | AD4: Participation (%)
A5: NSW | B5: Males | C5: 50–54 | D5: 26421 | E5: 108394 | F5: 24.4 | H5: 23763 | I5: 99410 | J5: 23.9 | L5: 36402 | M5: 142633 | N5: 25.5 | P5: 53684 | Q5: 196626 | R5: 27.3 | T5: 67540 | U5: 233424 | V5: 28.934471 | X5: 82345 | Y5: 271797 | Z5: 30.296508 | AB5: 84464 | AC5: 285976 | AD5: 29.535346
A6: NSW | B6: Males | C6: 55–59 | D6: 32124 | E6: 101229 | F6: 31.7 | H6: 30401 | I6: 98282 | J6: 30.9 | L6: 42821 | M6: 139861 | N6: 30.6 | P6: 46003 | Q6: 142636 | R6: 32.3 | T6: 46805 | U6: 139072 | V6: 33.655229 | X6: 60349 | Y6: 172330 | Z6: 35.019439 | AB6: 58699 | AC6: 175854 | AD6: 33.379394
A7: NSW | B7: Males | C7: 60–64 | D7: 35337 | E7: 94552 | F7: 37.4 | H7: 45509 | I7: 121437 | J7: 37.5 | L7: 59992 | M7: 159624 | N7: 37.6 | P7: 78127 | Q7: 204947 | R7: 38.1 | T7: 93732 | U7: 238788 | V7: 39.253229 | X7: 88409 | Y7: 208560 | Z7: 42.390199 | AB7: 90359 | AC7: 228883 | AD7: 39.478249
A8: NSW | B8: Males | C8: 65–69 | D8: 30764 | E8: 81280 | F8: 37.8 | H8: 30008 | I8: 76644 | J8: 39.2 | L8: 30035 | M8: 70505 | N8: 42.6 | P8: 46915 | Q8: 105565 | R8: 44.4 | T8: 63218 | U8: 138956 | V8: 45.494977 | X8: 59313 | Y8: 120448 | Z8: 49.243657 | AB8: 60226 | AC8: 130020 | AD8: 46.320566
A9: NSW | B9: Males | C9: 70–74 | D9: 21427 | E9: 44142 | F9: 48.5 | H9: 59483 | I9: 122475 | J9: 48.6 | L9: 76837 | M9: 159116 | N9: 48.3 | P9: 82458 | Q9: 169229 | R9: 48.7 | T9: 84649 | U9: 169823 | V9: 49.845427 | X9: 80129 | Y9: 150559 | Z9: 53.220996 | AB9: 80137 | AC9: 161651 | AD9: 49.574082
A10: NSW | B10: Males | C10: 50–74 | D10: 146073 | E10: 429597 | F10: 34 | H10: 189164 | I10: 518248 | J10: 36.5 | L10: 246087 | M10: 671739 | N10: 36.6 | P10: 307187 | Q10: 819003 | R10: 37.5 | T10: 355944 | U10: 920063 | V10: 38.686916 | X10: 370545 | Y10: 923694 | Z10: 40.115558 | AB10: 373885 | AC10: 982384 | AD10: 38.058946
A11: NSW | B11: Females | C11: 50–54 | D11: 29589 | E11: 107019 | F11: 27.6 | H11: 26663 | I11: 98185 | J11: 27.2 | L11: 40989 | M11: 143064 | N11: 28.7 | P11: 61389 | Q11: 198815 | R11: 30.9 | T11: 76493 | U11: 235401 | V11: 32.494764 | X11: 91688 | Y11: 278574 | Z11: 32.913337 | AB11: 92340 | AC11: 291804 | AD11: 31.644529
A12: NSW | B12: Females | C12: 55–59 | D12: 36864 | E12: 101181 | F12: 36.4 | H12: 34497 | I12: 98043 | J12: 35.2 | L12: 48669 | M12: 139453 | N12: 34.9 | P12: 52598 | Q12: 142804 | R12: 36.8 | T12: 53431 | U12: 140191 | V12: 38.113003 | X12: 67667 | Y12: 173448 | Z12: 39.012845 | AB12: 65098 | AC12: 173230 | AD12: 37.578941
A13: NSW | B13: Females | C13: 60–64 | D13: 40806 | E13: 95956 | F13: 42.5 | H13: 51446 | I13: 123375 | J13: 41.7 | L13: 68032 | M13: 162196 | N13: 41.9 | P13: 89980 | Q13: 209217 | R13: 43 | T13: 107340 | U13: 244605 | V13: 43.882995 | X13: 100134 | Y13: 215838 | Z13: 46.393128 | AB13: 100964 | AC13: 230825 | AD13: 43.740496
A14: NSW | B14: Females | C14: 65–69 | D14: 34267 | E14: 81612 | F14: 42 | H14: 33168 | I14: 76958 | J14: 43.1 | L14: 32581 | M14: 71035 | N14: 45.9 | P14: 51600 | Q14: 108012 | R14: 47.8 | T14: 69888 | U14: 141993 | V14: 49.219328 | X14: 65898 | Y14: 124821 | Z14: 52.794001 | AB14: 66593 | AC14: 133282 | AD14: 49.963986
A15: NSW | B15: Females | C15: 70–74 | D15: 22144 | E15: 44738 | F15: 49.5 | H15: 61333 | I15: 123548 | J15: 49.6 | L15: 78951 | M15: 159977 | N15: 49.4 | P15: 85767 | Q15: 170859 | R15: 50.2 | T15: 88468 | U15: 172229 | V15: 51.366495 | X15: 82534 | Y15: 153213 | Z15: 53.868797 | AB15: 82112 | AC15: 163590 | AD15: 50.193777
A16: NSW | B16: Females | C16: 50–74 | D16: 163670 | E16: 430506 | F16: 38 | H16: 207107 | I16: 520109 | J16: 39.8 | L16: 269222 | M16: 675725 | N16: 39.8 | P16: 341334 | Q16: 829707 | R16: 41.1 | T16: 395620 | U16: 934419 | V16: 42.338608 | X16: 407921 | Y16: 945894 | Z16: 43.125445 | AB16: 407107 | AC16: 992731 | AD16: 41.008793
... A166: Australia | B166: Persons | C166: 50–74 | D166: 1014327 | E166: 2608599 | F166: 38.9 | H166: 1298942 | I166: 3174835 | J166: 40.9 | L166: 1693430 | M166: 4100498 | N166: 41.3 | P166: 2149569 | Q166: 5074538 | R166: 42.4 | T166: 2497317 | U166: 5744244 | V166: 43.47512 | X166: 2523538 | Y166: 5758228 | Z166: 43.824906 | AB166: 2490265 | AC166: 6090979 | AD166: 40.884479
A168: Notes
A169: 1. State and territory refers to state and territory of residence.
A170: 2. Biennial screening was fully rolled out in 2020 to people aged 50–74. For earlier periods, the specific ages invited within the 50–74 age range included 55 and 65 in 2007; 50, 55 and 65 in 2008 to 2013; 50, 55, 60 and 65 in 2014; 50, 55, 60, 65, 70 and 74 in 2015; 50, 55, 60, 64, 65, 70, 72 and 74 in 2016; 50, 54, 55, 58, 60, 64, 68, 70, 72 and 74 in 2017; and 50, 54, 58, 60, 62, 64, 66, 68, 70, 72 and 74 in 2018 and 50, 52, 54, 56, 58, 60, 62, 64, 66, 68, 70, 72 and 74 in 2019.
A171: 3. These results calculate participation rates using the new NBCSP performance indicator specifications. This indicator now measures a 2-year invitation period and also excludes those who opted off or suspended participation. Therefore, these results cannot be compared to rates reported prior to 2014. For further information see the NBCSP performance indicator documentation (https://www.aihw.gov.au/reports-data/health-welfare-services/cancer-screening/indicators).
A172: 4. Each 2-year period covers from 1 January in the first year to 31 December in the following year. For example, 2017–2018 covers 1 January 2017 to 31 December 2018 inclusive.
A173: 5. These data are sourced from a live database, which is updated over time, with later data supply likely to have a greater level of completeness. This means that the data in this report may differ from data sourced at a different time.
A175: Source: AIHW analysis of National Bowel Cancer Screening Program (Department of Human Services) register data and National Cancer Screening Register data (NCSR RDE 14/01/2023).

Sheet NBCSP, Reparticipation
A1: Click to return to TOC
A2: Table 3: Reparticipation in the National Bowel Cancer Screening Program, by 5-year age group, people aged 50–74, 2015–2016 to 2020–2021
D3: 2015–2016 | H3: 2016–2017 | L3: 2017–2018 | P3: 2018–2019 | T3: 2019–2020 | X3: 2020–2021
A4: Invitation round | B4: Screened in previous invitation round? | C4: Age group | D4: Participated | E4: Invited | F4: Participation (%) | H4: Participated | I4: Invited | J4: Participation (%) | L4: Participated | M4: Invited | N4: Participation (%) | P4: Participated | Q4: Invited | R4: Participation (%) | T4: Participated | U4: Invited | V4: Participation (%) | X4: Participated | Y4: Invited | Z4: Participation (%)
A5: First | B5: n.a. | C5: 50–54 | D5: 213023 | E5: 621523 | F5: 27.9 | H5: 175798 | I5: 616542 | J5: 28.5 | L5: 197154 | M5: 650591 | N5: 30.3 | P5: 213023 | Q5: 654611 | R5: 32.5 | T5: 226133 | U5: 701053 | V5: 32.3 | X5: 228131 | Y5: 748193 | Z5: 30.5
A6: First | B6: n.a. | C6: 55–59 | D6: 3598 | E6: 13661 | F6: 26.3 | H6: 4069 | I6: 14845 | J6: 27.4 | L6: 3568 | M6: 11723 | N6: 30.4 | P6: 2841 | Q6: 8688 | R6: 32.7 | T6: 3894 | U6: 15651 | V6: 24.9 | X6: 3307 | Y6: 12432 | Z6: 26.6
A7: First | B7: n.a. | C7: 60–64 | D7: 5920 | E7: 18718 | F7: 31.6 | H7: 6917 | I7: 21001 | J7: 32.9 | L7: 6560 | M7: 18264 | N7: 35.9 | P7: 6270 | Q7: 16808 | R7: 37.3 | T7: 4827 | U7: 16828 | V7: 28.7 | X7: 3410 | Y7: 11366 | Z7: 30
A8: First | B8: n.a. | C8: 65–69 | D8: 144226 | E8: 336933 | F8: 42.8 | H8: 46764 | I8: 109365 | J8: 42.8 | L8: 2088 | M8: 5445 | N8: 38.3 | P8: 2990 | Q8: 7675 | R8: 39 | T8: 3092 | U8: 10471 | V8: 29.5 | X8: 1978 | Y8: 6968 | Z8: 28.4
A9: First | B9: n.a. | C9: 70–74 | D9: 24182 | E9: 53868 | F9: 44.9 | H9: 4921 | I9: 13948 | J9: 35.3 | L9: 3692 | M9: 10028 | N9: 36.8 | P9: 2444 | Q9: 6370 | R9: 38.4 | T9: 2553 | U9: 11331 | V9: 22.5 | X9: 2345 | Y9: 9647 | Z9: 24.3
A10: First | B10: n.a. | C10: 50–74 | D10: 351398 | E10: 1044703 | F10: 33.6 | H10: 238469 | I10: 775701 | J10: 30.7 | L10: 213062 | M10: 696051 | N10: 30.6 | P10: 227568 | Q10: 694152 | R10: 32.8 | T10: 240499 | U10: 755334 | V10: 31.8 | X10: 239171 | Y10: 788606 | Z10: 30.3
A11: Subsequent | B11: No | C11: 50–54 | D11: 1472 | E11: 2538 | F11: 58 | H11: 34271 | I11: 194485 | J11: 17.6 | L11: 76999 | M11: 423867 | N11: 18.2 | P11: 112718 | Q11: 596518 | R11: 18.9 | T11: 129168 | U11: 718322 | V11: 18 | X11: 111088 | Y11: 740917 | Z11: 15
A12: Subsequent | B12: No | C12: 55–59 | D12: 72237 | E12: 399856 | F12: 18.1 | H12: 100081 | I12: 567662 | J12: 17.6 | L12: 103600 | M12: 576118 | N12: 18 | P12: 106784 | Q12: 565414 | R12: 18.9 | T12: 126673 | U12: 686124 | V12: 18.5 | X12: 115109 | Y12: 715509 | Z12: 16.1
A13: Subsequent | B13: No | C13: 60–64 | D13: 96677 | E13: 444481 | F13: 21.8 | H13: 126050 | I13: 580940 | J13: 21.7 | L13: 154258 | M13: 750987 | N13: 20.5 | P13: 182480 | Q13: 877834 | R13: 20.8 | T13: 143761 | U13: 729223 | V13: 19.7 | X13: 136558 | Y13: 829783 | Z13: 16.5
A14: Subsequent | B14: No | C14: 65–69 | D14: 18763 | E14: 73631 | F14: 25.5 | H14: 43519 | I14: 177480 | J14: 24.5 | L14: 85453 | M14: 363887 | N14: 23.5 | P14: 113295 | Q14: 470626 | R14: 24.1 | T14: 83453 | U14: 369264 | V14: 22.6 | X14: 76940 | Y14: 413900 | Z14: 18.6
A15: Subsequent | B15: No | C15: 70–74 | D15: 79219 | E15: 326471 | F15: 24.3 | H15: 115803 | I15: 469044 | J15: 24.7 | L15: 125278 | M15: 514338 | N15: 24.4 | P15: 120337 | Q15: 515943 | R15: 23.3 | T15: 89406 | U15: 417973 | V15: 21.4 | X15: 86191 | Y15: 480506 | Z15: 17.9
A16: Subsequent | B16: No | C16: 50–74 | D16: 268368 | E16: 1246977 | F16: 21.5 | H16: 419724 | I16: 1989611 | J16: 21.1 | L16: 545588 | M16: 2629197 | N16: 20.8 | P16: 635614 | Q16: 3026335 | R16: 21 | T16: 572461 | U16: 2920906 | V16: 19.6 | X16: 525886 | Y16: 3180615 | Z16: 16.5
... A46: All rounds | B46: All | C46: 50–74 | D46: 1298942 | E46: 3174835 | F46: 40.9 | H46: 1693430 | I46: 4100498 | J46: 41.3 | L46: 2149569 | M46: 5074538 | N46: 42.4 | P46: 2497317 | Q46: 5744244 | R46: 43.5 | T46: 2523538 | U46: 5758228 | V46: 43.8 | X46: 2490265 | Y46: 6090979 | Z46: 40.9
A47: (a) Includes all first-round invitations.
A49: Notes
A50: 1. Biennial screening was fully rolled out in 2020 to people aged 50–74. For earlier periods, the specific ages invited within the 50–74 age range included 55 and 65 in 2007; 50, 55 and 65 in 2008 to 2013; 50, 55, 60 and 65 in 2014; 50, 55, 60, 65, 70 and 74 in 2015; 50, 55, 60, 64, 65, 70, 72 and 74 in 2016; 50, 54, 55, 58, 60, 64, 68, 70, 72 and 74 in 2017; and 50, 54, 58, 60, 62, 64, 66, 68, 70, 72 and 74 in 2018 and 50, 52, 54, 56, 58, 60, 62, 64, 66, 68, 70, 72 and 74 in 2019.
A51: 2. These results calculate participation rates using the new NBCSP performance indicator specifications. This indicator now measures a 2-year invitation period and also excludes those who opted off or suspended participation. For further information see the NBCSP performance indicator documentation (https://www.aihw.gov.au/reports-data/health-welfare-services/cancer-screening/indicators).
A52: 3. Rescreening invitations for some age groups only include manually reinvited people, leading to small numbers. Rates for those age groups are not representative of true reparticipation.
A53: 4. Each 2-year period covers from 1 January in the first year to 31 December in the following year. For example, 2017–2018 covers 1 January 2017 to 31 December 2018 inclusive.
A54: 5. Reparticipation rates by 5-year age groups is not available for the period 2014–2015 or earlier.
A55: 6. These data are sourced from a live database, which is updated over time, with later data supply likely to have a greater level of completeness. This means that the data in this report may differ from data sourced at a different time.
A57: Source: AIHW analysis of National Bowel Cancer Screening Program (Department of Human Services) register data and National Cancer Screening Register data (NCSR RDE 14/01/2023).

Sheet NBCSP, PHN 
A1: Click to return to TOC
A2: Table 4: Participation in the National Bowel Cancer Screening Program, by Primary Health Network area, people aged 50–74, 2014–2015 to 2020–2021
D3: 2014–2015 | H3: 2015–2016 | L3: 2016–2017 | P3: 2017–2018 | T3: 2018–2019 | X3: 2019–2020 | AB3: 2020–2021
A4: State/territory | B4: PHN code | C4: PHN name | D4: Participated | E4: Invited | F4: Participation (%) | H4: Participated | I4: Invited | J4: Participation (%) | L4: Participated | M4: Invited | N4: Participation (%) | P4: Participated | Q4: Invited | R4: Participation (%) | T4: Participated | U4: Invited | V4: Participation (%) | X4: Participated | Y4: Invited | Z4: Participation (%) | AB4: Participated | AC4: Invited | AD4: Participation (%)
A5: NSW | B5: PHN101 | C5: Central and Eastern Sydney | D5: 52039 | E5: 157280 | F5: 33.1 | H5: 64863 | I5: 186508 | J5: 34.8 | L5: 83365 | M5: 237308 | N5: 35.1 | P5: 107191 | Q5: 293747 | R5: 36.5 | T5: 123641 | U5: 326857 | V5: 37.827246 | X5: 132260 | Y5: 339678 | Z5: 38.936757 | AB5: 132758 | AC5: 356631 | AD5: 37.225576
A6: NSW | B6: PHN102 | C6: Northern Sydney | D6: 39723 | E6: 103788 | F6: 38.3 | H6: 49568 | I6: 123424 | J6: 40.2 | L6: 63820 | M6: 158335 | N6: 40.3 | P6: 81954 | Q6: 195865 | R6: 41.8 | T6: 94475 | U6: 218464 | V6: 43.245111 | X6: 99774 | Y6: 224328 | Z6: 44.476747 | AB6: 100537 | AC6: 233208 | AD6: 43.110265
A7: NSW | B7: PHN103 | C7: Western Sydney | D7: 30122 | E7: 92220 | F7: 32.7 | H7: 37526 | I7: 109418 | J7: 34.3 | L7: 48703 | M7: 140145 | N7: 34.8 | P7: 62061 | Q7: 174559 | R7: 35.6 | T7: 74641 | U7: 205496 | V7: 36.322362 | X7: 76879 | Y7: 204050 | Z7: 37.676378 | AB7: 77444 | AC7: 217694 | AD7: 35.574617
A8: NSW | B8: PHN104 | C8: Nepean Blue Mountains | D8: 14430 | E8: 42331 | F8: 34.1 | H8: 18077 | I8: 49414 | J8: 36.6 | L8: 23523 | M8: 63976 | N8: 36.8 | P8: 29848 | Q8: 78028 | R8: 38.3 | T8: 33794 | U8: 83209 | V8: 40.613395 | X8: 36819 | Y8: 89336 | Z8: 41.213348 | AB8: 36903 | AC8: 94243 | AD8: 39.157515
A9: NSW | B9: PHN105 | C9: South Western Sydney | D9: 33877 | E9: 103647 | F9: 32.7 | H9: 41807 | I9: 122019 | J9: 34.3 | L9: 55096 | M9: 158162 | N9: 34.8 | P9: 71045 | Q9: 197483 | R9: 36 | T9: 77944 | U9: 208461 | V9: 37.390207 | X9: 89514 | Y9: 231084 | Z9: 38.736707 | AB9: 90734 | AC9: 247225 | AD9: 36.70075
A10: NSW | B10: PHN106 | C10: South Eastern NSW | D10: 29569 | E10: 74364 | F10: 39.8 | H10: 38472 | I10: 91471 | J10: 42.1 | L10: 49865 | M10: 118724 | N10: 42 | P10: 62721 | Q10: 145358 | R10: 43.1 | T10: 72296 | U10: 163551 | V10: 44.203949 | X10: 74584 | Y10: 163798 | Z10: 45.534393 | AB10: 74761 | AC10: 172565 | AD10: 43.323683
A11: NSW | B11: PHN107 | C11: Western NSW | D11: 12443 | E11: 34380 | F11: 36.2 | H11: 16633 | I11: 43264 | J11: 38.4 | L11: 21676 | M11: 56913 | N11: 38.1 | P11: 26361 | Q11: 69026 | R11: 38.2 | T11: 29211 | U11: 74557 | V11: 39.17942 | X11: 30090 | Y11: 74800 | Z11: 40.226781 | AB11: 30168 | AC11: 80568 | AD11: 37.444568
A12: NSW | B12: PHN108 | C12: Hunter New England and Central Coast | D12: 56464 | E12: 146725 | F12: 38.5 | H12: 74962 | I12: 181236 | J12: 41.4 | L12: 96831 | M12: 236916 | N12: 40.9 | P12: 120907 | Q12: 288297 | R12: 41.9 | T12: 140326 | U12: 325500 | V12: 43.110906 | X12: 141147 | Y12: 319863 | Z12: 44.127242 | AB12: 140871 | AC12: 336416 | AD12: 41.874039
A13: NSW | B13: PHN109 | C13: North Coast | D13: 27751 | E13: 70087 | F13: 39.6 | H13: 36056 | I13: 85942 | J13: 42 | L13: 46217 | M13: 111362 | N13: 41.5 | P13: 57413 | Q13: 136779 | R13: 42 | T13: 64567 | U13: 150916 | V13: 42.783403 | X13: 66268 | Y13: 151343 | Z13: 43.786999 | AB13: 65551 | AC13: 159902 | AD13: 40.994549
A14: NSW | B14: PHN110 | C14: Murrumbidgee | D14: 10365 | E14: 27588 | F14: 37.6 | H14: 13980 | I14: 34607 | J14: 40.4 | L14: 18640 | M14: 45851 | N14: 40.7 | P14: 22488 | Q14: 54689 | R14: 41.1 | T14: 29641 | U14: 69355 | V14: 42.738087 | X14: 25113 | Y14: 58201 | Z14: 43.148085 | AB14: 25178 | AC14: 62458 | AD14: 40.312494
A15: Vic | B15: PHN201 | C15: North Western Melbourne | D15: 54838 | E15: 149429 | F15: 36.7 | H15: 69028 | I15: 180693 | J15: 38.2 | L15: 93037 | M15: 234787 | N15: 39.6 | P15: 121168 | Q15: 291671 | R15: 41.5 | T15: 135495 | U15: 315675 | V15: 42.922309 | X15: 150652 | Y15: 347686 | Z15: 43.329914 | AB15: 152659 | AC15: 372823 | AD15: 40.94676
A16: Vic | B16: PHN202 | C16: Eastern Melbourne | D16: 68706 | E16: 167111 | F16: 41.1 | H16: 87394 | I16: 202167 | J16: 43.2 | L16: 114725 | M16: 257276 | N16: 44.6 | P16: 146556 | Q16: 314506 | R16: 46.6 | T16: 162870 | U16: 344952 | V16: 47.215265 | X16: 170280 | Y16: 354321 | Z16: 48.058109 | AB16: 169656 | AC16: 372305 | AD16: 45.569139
... A35: NT | B35: PHN701 | C35: Northern Territory | D35: 6180 | E35: 21510 | F35: 28.7 | H35: 6782 | I35: 23765 | J35: 28.5 | L35: 8079 | M35: 28661 | N35: 28.2 | P35: 12430 | Q35: 42742 | R35: 29.1 | T35: 9429 | U35: 33174 | V35: 28.422861 | X35: 10310 | Y35: 39342 | Z35: 26.205124 | AB35: 11099 | AC35: 43840 | AD35: 25.318162
A36: Unknown | C36: Unknown | D36: 1326 | E36: 4014 | F36: 33 | H36: 2805 | I36: 7859 | J36: 35.7 | L36: 7934 | M36: 21284 | N36: 37.3 | P36: 2682 | Q36: 7489 | R36: 35.8 | T36: 29917 | U36: 74377 | V36: 40.2 | X36: 728 | Y36: 2711 | Z36: 26.85356 | AB36: 820 | AC36: 3004 | AD36: 27.2
A37: Australia | C37: Australia | D37: 1014327 | E37: 2608599 | F37: 38.9 | H37: 1298942 | I37: 3174835 | J37: 40.9 | L37: 1693430 | M37: 4100498 | N37: 41.3 | P37: 2149569 | Q37: 5074538 | R37: 42.4 | T37: 2497317 | U37: 5744244 | V37: 43.5 | X37: 2523538 | Y37: 5758228 | Z37: 43.824906 | AB37: 2490265 | AC37: 6090979 | AD37: 40.884479
A39: Notes
A40: 1. From the 2019-2020 period, PHNs were assigned to NBCSP invitees using a SA2 to PHN correspondence. Prior to the 2019-2020 period, PHNs were assigned to NBCSP invitees using an SA1 to PHN correspondence. For those invitees without reliable SA1 or SA2 details, PHNs were mapped with a postcode to PHN correspondence instead, some of which cross PHN boundaries and may lead to some minor inaccuracies in results.
A41: 2. Some invitee SA1 or SA2 codes and postcodes cannot be attributed to a PHN. These invitees were included in an 'Unknown' group where applicable.
A42: 3. PHN refers to PHN of residence.
A43: 4. PHN205 Murray includes Albury, NSW.
A44: 5. SA1 and SA2 are part of the ABS ASGS.
A45: 6. The time period of some PHN data presented is prior to the initiation of PHNs, which were in established in June 2015. For further details on PHN see the Department of Health’s website.
A46: 7. Biennial screening was fully rolled out in 2020 to people aged 50–74. For earlier periods, the specific ages invited within the 50–74 age range included 55 and 65 in 2007; 50, 55 and 65 in 2008 to 2013; 50, 55, 60 and 65 in 2014; 50, 55, 60, 65, 70 and 74 in 2015; 50, 55, 60, 64, 65, 70, 72 and 74 in 2016; 50, 54, 55, 58, 60, 64, 68, 70, 72 and 74 in 2017; and 50, 54, 58, 60, 62, 64, 66, 68, 70, 72 and 74 in 2018 and 50, 52, 54, 56, 58, 60, 62, 64, 66, 68, 70, 72 and 74 in 2019.
A47: 8. These results calculate participation rates using the new NBCSP performance indicator specifications. This indicator now measures a 2-year invitation period and also excludes those who opted off or suspended participation. For further information see the NBCSP performance indicator documentation (https://www.aihw.gov.au/reports-data/health-welfare-services/cancer-screening/indicators).
A48: 9. NBCSP participation rates per area are not related to bowel cancer incidence rates.
A49: 10. Each 2-year period covers from 1 January in the first year to 31 December in the following year. For example, 2017–2018 covers 1 January 2017 to 31 December 2018 inclusive.
A50: 11. The number of people in different PHNs may not sum to 'Australia' total due to rounding.
... A53: Source: AIHW analysis of National Bowel Cancer Screening Program (Department of Human Services) register data and National Cancer Screening Register data (NCSR RDE 14/01/2023).

Sheet NBCSP, SA3 2016
A1: Click to return to TOC
A2: Table 5a: Participation in the National Bowel Cancer Screening Program, by Statistical Area Level 3 (ASGS 2016), people aged 50–74, 2018–2019 to 2020–2021
D3: 2018–2019 | H3: 2019–2020 | L3: 2020–2021
A4: State/territory | B4: SA3 code | C4: SA3 name | D4: Participated | E4: Invited | F4: Participation (%) | H4: Participated | I4: Invited | J4: Participation (%) | L4: Participated | M4: Invited | N4: Participation (%)
A5: NSW | B5: 10102 | C5: Queanbeyan | D5: 5932 | E5: 13950 | F5: 42.52322 | H5: 6401 | I5: 14821 | J5: 43.187828 | L5: 6417 | M5: 15851 | N5: 40.5
A6: NSW | B6: 10103 | C6: Snowy Mountains | D6: 2398 | E6: 5401 | F6: 44.402175 | H6: 2477 | I6: 5492 | J6: 45.102554 | L6: 2448 | M6: 5902 | N6: 41.5
A7: NSW | B7: 10104 | C7: South Coast | D7: 12444 | E7: 25462 | F7: 48.871316 | H7: 12562 | I7: 25212 | J7: 49.825441 | L7: 12588 | M7: 26691 | N7: 47.2
A8: NSW | B8: 10105 | C8: Goulburn - Mulwaree | D8: 4203 | E8: 9793 | F8: 42.916585 | H8: 4357 | I8: 10084 | J8: 43.206132 | L8: 4389 | M8: 10773 | N8: 40.7
A9: NSW | B9: 10106 | C9: Young - Yass | D9: 4096 | E9: 9684 | F9: 42.296254 | H9: 4070 | I9: 9328 | J9: 43.629436 | L9: 4000 | M9: 9929 | N9: 40.3
A10: NSW | B10: 10201 | C10: Gosford | D10: 19636 | E10: 46547 | F10: 42.185899 | H10: 19744 | I10: 45767 | J10: 43.14029 | L10: 19686 | M10: 47708 | N10: 41.3
A11: NSW | B11: 10202 | C11: Wyong | D11: 16767 | E11: 41518 | F11: 40.384192 | H11: 17110 | I11: 41581 | J11: 41.148669 | L11: 16935 | M11: 43411 | N11: 39
A12: NSW | B12: 10301 | C12: Bathurst | D12: 4922 | E12: 11576 | F12: 42.519838 | H12: 5085 | I12: 11779 | J12: 43.170315 | L12: 5234 | M12: 12603 | N12: 41.5
A13: NSW | B13: 10302 | C13: Lachlan Valley | D13: 5976 | E13: 14988 | F13: 39.870508 | H13: 5886 | I13: 14477 | J13: 40.655412 | L13: 5880 | M13: 15492 | N13: 38
A14: NSW | B14: 10303 | C14: Lithgow - Mudgee | D14: 5309 | E14: 12931 | F14: 41.052928 | H14: 5306 | I14: 12631 | J14: 42.007713 | L14: 5277 | M14: 13343 | N14: 39.5
A15: NSW | B15: 10304 | C15: Orange | D15: 5988 | E15: 14071 | F15: 42.556924 | H15: 6198 | I15: 14131 | J15: 43.86108 | L15: 6118 | M15: 14963 | N15: 40.9
A16: NSW | B16: 10401 | C16: Clarence Valley | D16: 6986 | E16: 15959 | F16: 43.777796 | H16: 7045 | I16: 15573 | J16: 45.238289 | L16: 7022 | M16: 16533 | N16: 42.5
... A25: NSW | B25: 10701 | C25: Dapto - Port Kembla | D25: 7426 | E25: 18864 | F25: 39.365828 | H25: 7830 | I25: 18981 | J25: 41.251778 | L25: 7737 | M25: 19863 | N25: 39
A26: NSW | B26: 10702 | C26: Illawarra Catchment Reserve | D26: n.p. | E26: n.p. | F26: n.p. | H26: n.p. | I26: n.p. | J26: n.p. | L26: n.p. | M26: n.p. | N26: n.p.
A27: NSW | B27: 10703 | C27: Kiama - Shellharbour | D27: 10618 | E27: 23802 | F27: 44.607636 | H27: 10855 | I27: 23781 | J27: 45.645684 | L27: 10999 | M27: 25050 | N27: 43.9
A28: NSW | B28: 10704 | C28: Wollongong | D28: 13047 | E28: 29969 | F28: 43.534986 | H28: 13638 | I28: 30521 | J28: 44.683988 | L28: 13875 | M28: 31809 | N28: 43.6
A29: NSW | B29: 10801 | C29: Great Lakes | D29: 5188 | E29: 10699 | F29: 48.491439 | H29: 5234 | I29: 10677 | J29: 49.021329 | L29: 5173 | M29: 11269 | N29: 45.9
A30: NSW | B30: 10802 | C30: Kempsey - Nambucca | D30: 6629 | E30: 15843 | F30: 41.838067 | H30: 6646 | I30: 15672 | J30: 42.403794 | L30: 6518 | M30: 16634 | N30: 39.2
A31: NSW | B31: 10803 | C31: Lord Howe Island | D31: 53 | E31: 114 | F31: 46.491228 | H31: 50 | I31: 117 | J31: 42.735043 | L31: 56 | M31: 129 | N31: 43.4
A32: NSW | B32: 10804 | C32: Port Macquarie | D32: 10556 | E32: 23684 | F32: 44.569748 | H32: 10685 | I32: 23290 | J32: 45.878128 | L32: 10575 | M32: 24527 | N32: 43.1
A33: NSW | B33: 10805 | C33: Taree - Gloucester | D33: 8301 | E33: 17712 | F33: 46.866477 | H33: 8238 | I33: 17361 | J33: 47.451304 | L33: 8215 | M33: 18423 | N33: 44.6
A34: NSW | B34: 10901 | C34: Albury | D34: 7346 | E34: 15716 | F34: 46.742876 | H34: 7271 | I34: 15203 | J34: 47.825167 | L34: 7320 | M34: 16477 | N34: 44.4
A35: NSW | B35: 10902 | C35: Lower Murray | D35: 1352 | E35: 3195 | F35: 42.317762 | H35: 1331 | I35: 3054 | J35: 43.586016 | L35: 1341 | M35: 3296 | N35: 40.7
A36: NSW | B36: 10903 | C36: Upper Murray exc. Albury | D36: 5857 | E36: 12333 | F36: 47.490373 | H36: 5487 | I36: 11491 | J36: 47.750566 | L36: 5585 | M36: 12480 | N36: 44.8
A37: NSW | B37: 11001 | C37: Armidale | D37: 4225 | E37: 9454 | F37: 44.684182 | H37: 4380 | I37: 9679 | J37: 45.252604 | L37: 4348 | M37: 10090 | N37: 43.1
A38: NSW | B38: 11002 | C38: Inverell - Tenterfield | D38: 4529 | E38: 11128 | F38: 40.697387 | H38: 4367 | I38: 10555 | J38: 41.376577 | L38: 4290 | M38: 11281 | N38: 38
... A53: NSW | B53: 11502 | C53: Dural - Wisemans Ferry | D53: 3094 | E53: 7527 | F53: 41.105212 | H53: 3045 | I53: 7186 | J53: 42.372152 | L53: 3071 | M53: 7457 | N53: 41.2
A54: NSW | B54: 11503 | C54: Hawkesbury | D54: n.p. | E54: n.p. | F54: n.p. | H54: 2792 | I54: 6322 | J54: 44.169904 | L54: 2768 | M54: 6659 | N54: 41.6
A55: NSW | B55: 11504 | C55: Rouse Hill - McGraths Hill | D55: n.p. | E55: n.p. | F55: n.p. | H55: 3590 | I55: 8715 | J55: 41.191613 | L55: 3944 | M55: 9751 | N55: 40.5
A56: NSW | B56: 11601 | C56: Blacktown | D56: 10379 | E56: 29510 | F56: 35.170231 | H56: 10936 | I56: 30162 | J56: 36.257352 | L56: 11073 | M56: 32316 | N56: 34.3
A57: NSW | B57: 11602 | C57: Blacktown - North | D57: 6772 | E57: 18504 | F57: 36.598621 | H57: 7444 | I57: 19372 | J57: 38.428904 | L57: 7721 | M57: 21513 | N57: 35.9
A58: NSW | B58: 11603 | C58: Mount Druitt | D58: 7130 | E58: 23923 | F58: 29.802594 | H58: 7474 | I58: 24329 | J58: 30.720651 | L58: 7691 | M58: 26351 | N58: 29.2
A59: NSW | B59: 11701 | C59: Botany | D59: n.p. | E59: n.p. | F59: n.p. | H59: 3778 | I59: 10460 | J59: 36.120132 | L59: 3917 | M59: 11240 | N59: 34.9
A60: NSW | B60: 11702 | C60: Marrickville - Sydenham - Petersham | D60: 4406 | E60: 11643 | F60: 37.846292 | H60: 4727 | I60: 12217 | J60: 38.69158 | L60: 4817 | M60: 12851 | N60: 37.5
A61: NSW | B61: 11703 | C61: Sydney Inner City | D61: 12894 | E61: 36174 | F61: 35.644261 | H61: 15106 | I61: 42205 | J61: 35.791699 | L61: 15363 | M61: 45739 | N61: 33.6
A62: NSW | B62: 11801 | C62: Eastern Suburbs - North | D62: 9303 | E62: 27085 | F62: 34.347425 | H62: 10182 | I62: 29136 | J62: 34.946458 | L62: 10118 | M62: 30061 | N62: 33.7
...

Sheet NBCSP, SA3 2011
A1: Click to return to TOC
A2: Table 5b: Participation in the National Bowel Cancer Screening Program, by Statistical Area Level 3 (ASGS 2011), people aged 50–74, 2014–2015 to 2017–2018
D3: 2014–2015 | H3: 2015–2016 | L3: 2016–2017 | P3: 2017–2018
A4: State/territory | B4: SA3 code | C4: SA3 name | D4: Participated | E4: Invited | F4: Participation (%) | H4: Participated | I4: Invited | J4: Participation (%) | L4: Participated | M4: Invited | N4: Participation (%) | P4: Participated | Q4: Invited | R4: Participation (%)
A5: NSW | B5: 10101 | C5: Goulburn - Yass | D5: 3454 | E5: 8968 | F5: 38.5 | H5: 4547 | I5: 11087 | J5: 41 | L5: 5905 | M5: 14469 | N5: 40.8 | P5: 7149 | Q5: 17351 | R5: 41.2
A6: NSW | B6: 10102 | C6: Queanbeyan | D6: 2512 | E6: 6451 | F6: 38.9 | H6: 2989 | I6: 7543 | J6: 39.6 | L6: 3972 | M6: 9948 | N6: 39.9 | P6: 5104 | Q6: 12205 | R6: 41.8
A7: NSW | B7: 10103 | C7: Snowy Mountains | D7: 989 | E7: 2469 | F7: 40.1 | H7: 1297 | I7: 2999 | J7: 43.3 | L7: 1650 | M7: 3951 | N7: 41.8 | P7: 2062 | Q7: 4879 | R7: 42.3
A8: NSW | B8: 10104 | C8: South Coast | D8: 4887 | E8: 11062 | F8: 44.2 | H8: 6529 | I8: 14099 | J8: 46.3 | L8: 8576 | M8: 18320 | N8: 46.8 | P8: 10843 | Q8: 22597 | R8: 48
A9: NSW | B9: 10201 | C9: Gosford | D9: 7926 | E9: 21628 | F9: 36.6 | H9: 10549 | I9: 27009 | J9: 39.1 | L9: 13531 | M9: 34527 | N9: 39.2 | P9: 17061 | Q9: 41600 | R9: 41
A10: NSW | B10: 10202 | C10: Wyong | D10: 6758 | E10: 18723 | F10: 36.1 | H10: 8900 | I10: 23448 | J10: 38 | L10: 11432 | M10: 30464 | N10: 37.5 | P10: 14334 | Q10: 36708 | R10: 39
A11: NSW | B11: 10301 | C11: Bathurst | D11: 2048 | E11: 5299 | F11: 38.7 | H11: 2632 | I11: 6420 | J11: 41 | L11: 3366 | M11: 8250 | N11: 40.8 | P11: 4245 | Q11: 10160 | R11: 41.8
A12: NSW | B12: 10302 | C12: Lachlan Valley | D12: 2415 | E12: 6656 | F12: 36.3 | H12: 3301 | I12: 8373 | J12: 39.4 | L12: 4339 | M12: 11285 | N12: 38.4 | P12: 5221 | Q12: 13592 | R12: 38.4
A13: NSW | B13: 10303 | C13: Lithgow - Mudgee | D13: 2169 | E13: 5961 | F13: 36.4 | H13: 2944 | I13: 7426 | J13: 39.6 | L13: 3799 | M13: 9542 | N13: 39.8 | P13: 4507 | Q13: 11318 | R13: 39.8
A14: NSW | B14: 10304 | C14: Orange | D14: 2505 | E14: 6513 | F14: 38.5 | H14: 3234 | I14: 7868 | J14: 41.1 | L14: 4116 | M14: 10333 | N14: 39.8 | P14: 5095 | Q14: 12540 | R14: 40.6
A15: NSW | B15: 10401 | C15: Clarence Valley | D15: 2998 | E15: 7406 | F15: 40.5 | H15: 4040 | I15: 9377 | J15: 43.1 | L15: 4921 | M15: 11729 | N15: 42 | P15: 6018 | Q15: 14132 | R15: 42.6
A16: NSW | B16: 10402 | C16: Coffs Harbour | D16: 4922 | E16: 12285 | F16: 40.1 | H16: 6200 | I16: 14594 | J16: 42.5 | L16: 8026 | M16: 18665 | N16: 43 | P16: 9997 | Q16: 23023 | R16: 43.4
... A24: NSW | B24: 10701 | C24: Dapto - Port Kembla | D24: 3061 | E24: 8863 | F24: 34.5 | H24: 3979 | I24: 10792 | J24: 36.9 | L24: 5237 | M24: 14075 | N24: 37.2 | P24: 6413 | Q24: 16994 | R24: 37.7
A25: NSW | B25: 10702 | C25: Illawarra Catchment Reserve | D25: n.p. | E25: n.p. | F25: n.p. | H25: n.p. | I25: n.p. | J25: n.p. | L25: n.p. | M25: n.p. | N25: n.p. | P25: n.p. | Q25: n.p. | R25: n.p.
A26: NSW | B26: 10703 | C26: Kiama - Shellharbour | D26: 4299 | E26: 10997 | F26: 39.1 | H26: 5542 | I26: 13273 | J26: 41.8 | L26: 7167 | M26: 17173 | N26: 41.7 | P26: 9065 | Q26: 21147 | R26: 42.9
A27: NSW | B27: 10704 | C27: Wollongong | D27: 5557 | E27: 14367 | F27: 38.7 | H27: 6941 | I27: 17219 | J27: 40.3 | L27: 8826 | M27: 22087 | N27: 40 | P27: 11308 | Q27: 27030 | R27: 41.8
A28: NSW | B28: 10801 | C28: Great Lakes | D28: 1953 | E28: 4437 | F28: 44 | H28: 2789 | I28: 5931 | J28: 47 | L28: 3662 | M28: 7960 | N28: 46 | P28: 4547 | Q28: 9614 | R28: 47.3
A29: NSW | B29: 10802 | C29: Kempsey - Nambucca | D29: 2720 | E29: 7064 | F29: 38.5 | H29: 3516 | I29: 8630 | J29: 40.7 | L29: 4606 | M29: 11362 | N29: 40.5 | P29: 5837 | Q29: 14048 | R29: 41.6
A30: NSW | B30: 10803 | C30: Lord Howe Island | D30: n.p. | E30: n.p. | F30: n.p. | H30: n.p. | I30: n.p. | J30: n.p. | L30: n.p. | M30: n.p. | N30: n.p. | P30: n.p. | Q30: n.p. | R30: n.p.
A31: NSW | B31: 10804 | C31: Port Macquarie | D31: 4296 | E31: 10247 | F31: 41.9 | H31: 5841 | I31: 13145 | J31: 44.4 | L31: 7560 | M31: 17339 | N31: 43.6 | P31: 9235 | Q31: 21126 | R31: 43.7
A32: NSW | B32: 10805 | C32: Taree - Gloucester | D32: 3197 | E32: 7712 | F32: 41.5 | H32: 4514 | I32: 9837 | J32: 45.9 | L32: 5905 | M32: 12907 | N32: 45.7 | P32: 7330 | Q32: 15870 | R32: 46.2
A33: NSW | B33: 10901 | C33: Albury | D33: 2848 | E33: 6864 | F33: 41.5 | H33: 3777 | I33: 8729 | J33: 43.3 | L33: 5171 | M33: 11806 | N33: 43.8 | P33: 6478 | Q33: 14060 | R33: 46.1
A34: NSW | B34: 10902 | C34: Lower Murray | D34: 520 | E34: 1417 | F34: 36.7 | H34: 748 | I34: 1911 | J34: 39.1 | L34: 997 | M34: 2463 | N34: 40.5 | P34: 1170 | Q34: 2873 | R34: 40.7
A35: NSW | B35: 10903 | C35: Upper Murray exc. Albury | D35: 2322 | E35: 5397 | F35: 43 | H35: 3112 | I35: 6944 | J35: 44.8 | L35: 4157 | M35: 9186 | N35: 45.3 | P35: 5229 | Q35: 11071 | R35: 47.2
A36: NSW | B36: 11001 | C36: Armidale | D36: 1911 | E36: 4569 | F36: 41.8 | H36: 2435 | I36: 5456 | J36: 44.6 | L36: 2990 | M36: 6960 | N36: 43 | P36: 3746 | Q36: 8502 | R36: 44.1
A37: NSW | B37: 11002 | C37: Inverell - Tenterfield | D37: 1858 | E37: 4940 | F37: 37.6 | H37: 2434 | I37: 6276 | J37: 38.8 | L37: 3235 | M37: 8315 | N37: 38.9 | P37: 3930 | Q37: 10008 | R37: 39.3
A38: NSW | B38: 11003 | C38: Moree - Narrabri | D38: 918 | E38: 2845 | F38: 32.3 | H38: 1167 | I38: 3603 | J38: 32.4 | L38: 1519 | M38: 4819 | N38: 31.5 | P38: 1821 | Q38: 5674 | R38: 32.1
A39: NSW | B39: 11004 | C39: Tamworth - Gunnedah | D39: 3595 | E39: 9283 | F39: 38.7 | H39: 4786 | I39: 11733 | J39: 40.8 | L39: 6130 | M39: 15603 | N39: 39.3 | P39: 7299 | Q39: 18466 | R39: 39.5
A40: NSW | B40: 11101 | C40: Lake Macquarie - East | D40: 6172 | E40: 15124 | F40: 40.8 | H40: 8197 | I40: 18238 | J40: 44.9 | L40: 10449 | M40: 23797 | N40: 43.9 | P40: 13124 | Q40: 29178 | R40: 45
A41: NSW | B41: 11102 | C41: Lake Macquarie - West | D41: 3807 | E41: 9384 | F41: 40.6 | H41: 5044 | I41: 11477 | J41: 43.9 | L41: 6551 | M41: 15151 | N41: 43.2 | P41: 8157 | Q41: 18726 | R41: 43.6
A42: NSW | B42: 11103 | C42: Newcastle | D42: 6983 | E42: 18192 | F42: 38.4 | H42: 9000 | I42: 21806 | J42: 41.3 | L42: 11614 | M42: 28251 | N42: 41.1 | P42: 14705 | Q42: 34491 | R42: 42.6
... A80: NSW | B80: 12401 | C80: Blue Mountains | D80: 4232 | E80: 10897 | F80: 38.8 | H80: 5380 | I80: 12848 | J80: 41.9 | L80: 6894 | M80: 16652 | N80: 41.4 | P80: 8646 | Q80: 20175 | R80: 42.9
A81: NSW | B81: 12402 | C81: Blue Mountains - South | D81: n.p. | E81: n.p. | F81: n.p. | H81: n.p. | I81: n.p. | J81: n.p. | L81: n.p. | M81: n.p. | N81: n.p. | P81: n.p. | Q81: n.p. | R81: n.p.
A82: NSW | B82: 12403 | C82: Penrith | D82: 4719 | E82: 14449 | F82: 32.7 | H82: 5929 | I82: 16959 | J82: 35 | L82: 7752 | M82: 21703 | N82: 35.7 | P82: 9847 | Q82: 26695 | R82: 36.9
A83: NSW | B83: 12404 | C83: Richmond - Windsor | D83: 1216 | E83: 3919 | F83: 31 | H83: 1505 | I83: 4513 | J83: 33.3 | L83: 2029 | M83: 6006 | N83: 33.8 | P83: 2628 | Q83: 7399 | R83: 35.5
A84: NSW | B84: 12405 | C84: St Marys | D84: 1815 | E84: 6199 | F84: 29.3 | H84: 2192 | I84: 7127 | J84: 30.8 | L84: 2879 | M84: 9204 | N84: 31.3 | P84: 3712 | Q84: 11207 | R84: 33.1
...

Sheet NBCSP, SA2 2016 
A1: Click to return to TOC
A2: Table 6a: Participation in the National Bowel Cancer Screening Program by Statistical Area Level 2 (ASGS 2016), people aged 50–74, 2019-2020 to 2020–2021
E3: 2019–2020 | I3: 2020–2021
A4: State/territory | B4: SA2 Code | C4: SA2 Name | D4: Age group | E4: Participated | F4: Invited | G4: Particpation (%) | I4: Participated | J4: Invited | K4: Particpation (%)
A5: NSW | B5: 101021007 | C5: Braidwood | D5: 50–74 | E5: 576 | F5: 1305 | G5: 44.139109 | I5: 598 | J5: 1450 | K5: 41.233932
A6: NSW | B6: 101021008 | C6: Karabar | D6: 50–74 | E6: 726 | F6: 1958 | G6: 37.088706 | I6: 712 | J6: 2059 | K6: 34.54982
A7: NSW | B7: 101021009 | C7: Queanbeyan | D7: 50–74 | E7: 822 | F7: 2215 | G7: 37.121564 | I7: 835 | J7: 2430 | K7: 34.364109
A8: NSW | B8: 101021010 | C8: Queanbeyan - East | D8: 50–74 | E8: 374 | F8: 966 | G8: 38.681967 | I8: 384 | J8: 1050 | K8: 36.596497
A9: NSW | B9: 101021011 | C9: Queanbeyan Region | D9: 50–74 | E9: 2589 | F9: 5446 | G9: 47.533029 | I9: 2554 | J9: 5751 | K9: 44.408143
A10: NSW | B10: 101021012 | C10: Queanbeyan West - Jerrabomberra | D10: 50–74 | E10: 1314 | F10: 2931 | G10: 44.834226 | I10: 1334 | J10: 3110 | K10: 42.90586
A11: NSW | B11: 101031013 | C11: Bombala | D11: 50–74 | E11: 367 | F11: 748 | G11: 49.048058 | I11: 354 | J11: 794 | K11: 44.570855
A12: NSW | B12: 101031014 | C12: Cooma | D12: 50–74 | E12: 933 | F12: 2094 | G12: 44.548974 | I12: 928 | J12: 2210 | K12: 41.99951
A13: NSW | B13: 101031015 | C13: Cooma Region | D13: 50–74 | E13: 366 | F13: 848 | G13: 43.142791 | I13: 348 | J13: 937 | K13: 37.134575
A14: NSW | B14: 101031016 | C14: Jindabyne - Berridale | D14: 50–74 | E14: 811 | F14: 1801 | G14: 45.030228 | I14: 818 | J14: 1961 | K14: 41.713231
A15: NSW | B15: 101041017 | C15: Batemans Bay | D15: 50–74 | E15: 1454 | F15: 3104 | G15: 46.836189 | I15: 1435 | J15: 3290 | K15: 43.618691
A16: NSW | B16: 101041018 | C16: Batemans Bay - South | D16: 50–74 | E16: 1129 | F16: 2364 | G16: 47.748554 | I16: 1142 | J16: 2554 | K16: 44.715241
... A19: NSW | B19: 101041021 | C19: Broulee - Tomakin | D19: 50–74 | E19: 893 | F19: 1744 | G19: 51.224908 | I19: 901 | J19: 1816 | K19: 49.637589
A20: NSW | B20: 101041022 | C20: Deua - Wadbilliga | D20: 50–74 | E20: n.p. | F20: n.p. | G20: n.p. | I20: n.p. | J20: n.p. | K20: n.p.
A21: NSW | B21: 101041023 | C21: Eden | D21: 50–74 | E21: 606 | F21: 1231 | G21: 49.22827 | I21: 581 | J21: 1281 | K21: 45.355191
A22: NSW | B22: 101041024 | C22: Eurobodalla Hinterland | D22: 50–74 | E22: 495 | F22: 1039 | G22: 47.635506 | I22: 486 | J22: 1110 | K22: 43.824601
A23: NSW | B23: 101041025 | C23: Merimbula - Tura Beach | D23: 50–74 | E23: 2099 | F23: 3873 | G23: 54.195811 | I23: 2091 | J23: 4069 | K23: 51.39125
A24: NSW | B24: 101041026 | C24: Moruya - Tuross Head | D24: 50–74 | E24: 1159 | F24: 2404 | G24: 48.197326 | I24: 1176 | J24: 2621 | K24: 44.887266
A25: NSW | B25: 101041027 | C25: Narooma - Bermagui | D25: 50–74 | E25: 1814 | F25: 3552 | G25: 51.070053 | I25: 1808 | J25: 3704 | K25: 48.812309
A26: NSW | B26: 101051539 | C26: Goulburn | D26: 50–74 | E26: 2675 | F26: 6225 | G26: 42.970472 | I26: 2684 | J26: 6631 | K26: 40.480701
A27: NSW | B27: 101051540 | C27: Goulburn Region | D27: 50–74 | E27: 1682 | F27: 3859 | G27: 43.586218 | I27: 1705 | J27: 4141 | K27: 41.158814
A28: NSW | B28: 101061541 | C28: Yass | D28: 50–74 | E28: 811 | F28: 1825 | G28: 44.412519 | I28: 793 | J28: 1948 | K28: 40.710279
A29: NSW | B29: 101061542 | C29: Yass Region | D29: 50–74 | E29: 1270 | F29: 2767 | G29: 45.90435 | I29: 1270 | J29: 2953 | K29: 43.004157
A30: NSW | B30: 101061543 | C30: Young | D30: 50–74 | E30: 1141 | F30: 2690 | G30: 42.41882 | I30: 1101 | J30: 2846 | K30: 38.686411
A31: NSW | B31: 101061544 | C31: Young Region | D31: 50–74 | E31: 848 | F31: 2046 | G31: 41.445784 | I31: 836 | J31: 2182 | K31: 38.311307
A32: NSW | B32: 102011028 | C32: Avoca Beach - Copacabana | D32: 50–74 | E32: 840 | F32: 1813 | G32: 46.334739 | I32: 839 | J32: 1926 | K32: 43.565664
... A78: NSW | B78: 103031074 | C78: Mudgee Region - West | D78: 50–74 | E78: 1137 | F78: 2785 | G78: 40.827169 | I78: 1126 | J78: 2937 | K78: 38.346015
A79: NSW | B79: 103031075 | C79: Wollangambe - Wollemi | D79: 50–74 | E79: n.p. | F79: n.p. | G79: n.p. | I79: n.p. | J79: n.p. | K79: n.p.
A80: NSW | B80: 103041076 | C80: Blayney | D80: 50–74 | E80: 920 | F80: 2070 | G80: 44.438844 | I80: 874 | J80: 2180 | K80: 40.080501
A81: NSW | B81: 103041077 | C81: Orange | D81: 50–74 | E81: 2358 | F81: 5549 | G81: 42.490909 | I81: 2277 | J81: 5771 | K81: 39.452939
A82: NSW | B82: 103041078 | C82: Orange - North | D82: 50–74 | E82: 1694 | F82: 3875 | G82: 43.711178 | I82: 1745 | J82: 4261 | K82: 40.948746
A83: NSW | B83: 103041079 | C83: Orange Region | D83: 50–74 | E83: 1226 | F83: 2636 | G83: 46.512094 | I83: 1223 | J83: 2752 | K83: 44.439733
A84: NSW | B84: 104011080 | C84: Grafton | D84: 50–74 | E84: 2394 | F84: 5493 | G84: 43.589131 | I84: 2398 | J84: 5854 | K84: 40.96378
A85: NSW | B85: 104011081 | C85: Grafton Region | D85: 50–74 | E85: 1920 | F85: 4495 | G85: 42.703968 | I85: 1896 | J85: 4780 | K85: 39.673532
A86: NSW | B86: 104011082 | C86: Maclean - Yamba - Iluka | D86: 50–74 | E86: 2731 | F86: 5585 | G86: 48.900237 | I86: 2728 | J86: 5900 | K86: 46.237084
A87: NSW | B87: 104021083 | C87: Bellingen | D87: 50–74 | E87: 859 | F87: 1923 | G87: 44.669787 | I87: 848 | J87: 2052 | K87: 41.318837
...

Sheet NBCSP, SA2 2011
A1: Click to return to TOC
A2: Table 6b: Participation in the National Bowel Cancer Screening Program, by Statistical Area Level 2 (AGSG 2011), people aged 50–74, 2015–2016 to 2017–2018
D3: 2015–2016 | H3: 2016–2017 | L3: 2017–2018
A4: State/territory | B4: SA2 code | C4: SA2 name | D4: Participated | E4: Invited | F4: Participation (%) | H4: Participated | I4: Invited | J4: Participation (%) | L4: Participated | M4: Invited | N4: Participation (%)
A5: NSW | B5: 101011001 | C5: Goulburn | D5: 1386 | E5: 3385 | F5: 40.9 | H5: 1803 | I5: 4472 | J5: 40.3 | L5: 2304 | M5: 5516 | N5: 41.8
A6: NSW | B6: 101011002 | C6: Goulburn Region | D6: 882 | E6: 2098 | F6: 42 | H6: 1096 | I6: 2621 | J6: 41.8 | L6: 1305 | M6: 3126 | N6: 41.8
A7: NSW | B7: 101011003 | C7: Yass | D7: 340 | E7: 864 | F7: 39.3 | H7: 445 | I7: 1154 | J7: 38.6 | L7: 653 | M7: 1595 | N7: 40.9
A8: NSW | B8: 101011004 | C8: Yass Region | D8: 749 | E8: 1782 | F8: 42 | H8: 999 | I8: 2345 | J8: 42.6 | L8: 1113 | M8: 2607 | N8: 42.7
A9: NSW | B9: 101011005 | C9: Young | D9: 684 | E9: 1669 | F9: 41 | H9: 914 | I9: 2175 | J9: 42 | L9: 996 | M9: 2540 | N9: 39.2
A10: NSW | B10: 101011006 | C10: Young Region | D10: 507 | E10: 1288 | F10: 39.3 | H10: 649 | I10: 1704 | J10: 38.1 | L10: 777 | M10: 1967 | N10: 39.5
A11: NSW | B11: 101021007 | C11: Braidwood | D11: 284 | E11: 683 | F11: 41.6 | H11: 389 | I11: 919 | J11: 42.4 | L11: 496 | M11: 1114 | N11: 44.6
A12: NSW | B12: 101021008 | C12: Karabar | D12: 416 | E12: 1249 | F12: 33.4 | H12: 539 | I12: 1677 | J12: 32.2 | L12: 666 | M12: 1909 | N12: 34.9
A13: NSW | B13: 101021009 | C13: Queanbeyan | D13: 392 | E13: 1116 | F13: 35.1 | H13: 516 | I13: 1469 | J13: 35.1 | L13: 865 | M13: 2261 | N13: 38.3
A14: NSW | B14: 101021010 | C14: Queanbeyan - East | D14: 196 | E14: 520 | F14: 37.8 | H14: 267 | I14: 702 | J14: 38.1 | L14: 320 | M14: 782 | N14: 40.9
A15: NSW | B15: 101021011 | C15: Queanbeyan Region | D15: 1040 | E15: 2388 | F15: 43.5 | H15: 1434 | I15: 3186 | J15: 45 | L15: 1703 | M15: 3731 | N15: 45.6
A16: NSW | B16: 101021012 | C16: Queanbeyan West - Jerrabomberra | D16: 661 | E16: 1587 | F16: 41.6 | H16: 825 | I16: 1996 | J16: 41.4 | L16: 1054 | M16: 2408 | N16: 43.8
... A25: NSW | B25: 101041021 | C25: Broulee - Tomakin | D25: 253 | E25: 529 | F25: 47.9 | H25: 325 | I25: 682 | J25: 47.7 | L25: 431 | M25: 878 | N25: 49.1
A26: NSW | B26: 101041022 | C26: Deua - Wadbilliga | D26: n.p. | E26: n.p. | F26: n.p. | H26: n.p. | I26: n.p. | J26: n.p. | L26: n.p. | M26: n.p. | N26: n.p.
A27: NSW | B27: 101041023 | C27: Eden | D27: 286 | E27: 652 | F27: 43.8 | H27: 371 | I27: 834 | J27: 44.4 | L27: 493 | M27: 1050 | N27: 46.9
A28: NSW | B28: 101041024 | C28: Eurobodalla Hinterland | D28: 269 | E28: 627 | F28: 43 | H28: 367 | I28: 824 | J28: 44.6 | L28: 415 | M28: 959 | N28: 43.2
A29: NSW | B29: 101041025 | C29: Merimbula - Tura Beach | D29: 1042 | E29: 2100 | F29: 49.6 | H29: 1369 | I29: 2707 | J29: 50.6 | L29: 1790 | M29: 3417 | N29: 52.4
A30: NSW | B30: 101041026 | C30: Moruya - Tuross Head | D30: 794 | E30: 1717 | F30: 46.3 | H30: 1027 | I30: 2228 | J30: 46.1 | L30: 1281 | M30: 2744 | N30: 46.7
A31: NSW | B31: 101041027 | C31: Narooma - Bermagui | D31: 973 | E31: 2025 | F31: 48 | H31: 1272 | I31: 2585 | J31: 49.2 | L31: 1553 | M31: 3158 | N31: 49.2
A32: NSW | B32: 102011028 | C32: Avoca Beach - Copacabana | D32: 499 | E32: 1271 | F32: 39.2 | H32: 566 | I32: 1411 | J32: 40.1 | L32: 793 | M32: 1845 | N32: 43
A33: NSW | B33: 102011029 | C33: Box Head - MacMasters Beach | D33: 827 | E33: 1981 | F33: 41.8 | H33: 1032 | I33: 2524 | J33: 40.9 | L33: 1314 | M33: 2991 | N33: 43.9
A34: NSW | B34: 102011030 | C34: Calga - Kulnura | D34: 309 | E34: 890 | F34: 34.7 | H34: 380 | I34: 1108 | J34: 34.3 | L34: 449 | M34: 1348 | N34: 33.3
A35: NSW | B35: 102011031 | C35: Erina - Green Point | D35: 963 | E35: 2375 | F35: 40.5 | H35: 1258 | I35: 3086 | J35: 40.8 | L35: 1523 | M35: 3628 | N35: 42
A36: NSW | B36: 102011032 | C36: Gosford - Springfield | D36: 787 | E36: 2213 | F36: 35.6 | H36: 996 | I36: 2748 | J36: 36.2 | L36: 1280 | M36: 3422 | N36: 37.4
A37: NSW | B37: 102011033 | C37: Kariong | D37: 314 | E37: 911 | F37: 34.5 | H37: 413 | I37: 1200 | J37: 34.5 | L37: 500 | M37: 1394 | N37: 35.9
A38: NSW | B38: 102011034 | C38: Kincumber - Picketts Valley | D38: 481 | E38: 1182 | F38: 40.7 | H38: 671 | I38: 1568 | J38: 42.8 | L38: 838 | M38: 1946 | N38: 43
... A78: NSW | B78: 103031074 | C78: Mudgee Region - West | D78: 677 | E78: 1646 | F78: 41.1 | H78: 861 | I78: 2091 | J78: 41.2 | L78: 954 | M78: 2413 | N78: 39.5
A79: NSW | B79: 103031075 | C79: Wollangambe - Wollemi | D79: n.p. | E79: n.p. | F79: n.p. | H79: n.p. | I79: n.p. | J79: n.p. | L79: n.p. | M79: n.p. | N79: n.p.
A80: NSW | B80: 103041076 | C80: Blayney | D80: 440 | E80: 1102 | F80: 40 | H80: 553 | I80: 1442 | J80: 38.3 | L80: 676 | M80: 1734 | N80: 39
A81: NSW | B81: 103041077 | C81: Orange | D81: 1109 | E81: 2825 | F81: 39.3 | H81: 1380 | I81: 3631 | J81: 38 | L81: 1717 | M81: 4434 | N81: 38.7
A82: NSW | B82: 103041078 | C82: Orange - North | D82: 968 | E82: 2313 | F82: 41.9 | H82: 1274 | I82: 3155 | J82: 40.4 | L82: 1602 | M82: 3841 | N82: 41.7
A83: NSW | B83: 103041079 | C83: Orange Region | D83: 716 | E83: 1628 | F83: 44 | H83: 909 | I83: 2105 | J83: 43.2 | L83: 1100 | M83: 2531 | N83: 43.5
A84: NSW | B84: 104011080 | C84: Grafton | D84: 1307 | E84: 3001 | F84: 43.5 | H84: 1534 | I84: 3704 | J84: 41.4 | L84: 1983 | M84: 4753 | N84: 41.7
A85: NSW | B85: 104011081 | C85: Grafton Region | D85: 1266 | E85: 3068 | F85: 41.3 | H85: 1563 | I85: 3808 | J85: 41.1 | L85: 1800 | M85: 4279 | N85: 42.1
A86: NSW | B86: 104011082 | C86: Maclean - Yamba - Iluka | D86: 1467 | E86: 3308 | F86: 44.4 | H86: 1824 | I86: 4216 | J86: 43.3 | L86: 2236 | M86: 5099 | N86: 43.8
A87: NSW | B87: 104021083 | C87: Bellingen | D87: 467 | E87: 1120 | F87: 41.7 | H87: 609 | I87: 1430 | J87: 42.6 | L87: 688 | M87: 1682 | N87: 40.9
...

Sheet NBCSP, Activity-Invites-State-
A1: Click to return to TOC
A2: Table 7: Number of screening invitations issued by the National Bowel Cancer Screening Program, by quarter, month, sex and state/territory, people aged 50–74, January 2014 to March 2023
C3: Males | M3: Females | W3: Persons
A4: Period (quarter) | B4: Month | C4: NSW | D4: VIC | E4: QLD | F4: WA | G4: SA | H4: TAS | I4: ACT | J4: NT | K4: Australia | M4: NSW | N4: VIC | O4: QLD | P4: WA | Q4: SA | R4: TAS | S4: ACT | T4: NT | U4: Australia | W4: NSW | X4: VIC | Y4: QLD | Z4: WA | AA4: SA | AB4: TAS | AC4: ACT | AD4: NT | AE4: Australia
A5: March quarter 2014 | B5: January | C5: 14438 | D5: 10671 | E5: 6891 | F5: 2067 | G5: 3072 | H5: 1050 | I5: 675 | J5: . | K5: 38864 | M5: 14305 | N5: 10821 | O5: 7000 | P5: 2020 | Q5: 3299 | R5: 1193 | S5: 761 | T5: . | U5: 39399 | W5: 28743 | X5: 21492 | Y5: 13891 | Z5: 4087 | AA5: 6371 | AB5: 2243 | AC5: 1436 | AD5: . | AE5: 78263
B6: February | C6: 19716 | D6: 14511 | E6: 10028 | F6: 3342 | G6: 4327 | H6: 1421 | I6: 975 | J6: . | K6: 54320 | M6: 19694 | N6: 15015 | O6: 10315 | P6: 3288 | Q6: 4402 | R6: 1585 | S6: 1011 | T6: . | U6: 55310 | W6: 39410 | X6: 29526 | Y6: 20343 | Z6: 6630 | AA6: 8729 | AB6: 3006 | AC6: 1986 | AD6: . | AE6: 109630
B7: March | C7: 28470 | D7: 19859 | E7: 16296 | F7: 8063 | G7: 6449 | H7: 2000 | I7: 1321 | J7: 76 | K7: 82534 | M7: 28358 | N7: 20342 | O7: 16229 | P7: 8125 | Q7: 6490 | R7: 2009 | S7: 1447 | T7: 92 | U7: 83092 | W7: 56828 | X7: 40201 | Y7: 32525 | Z7: 16188 | AA7: 12939 | AB7: 4009 | AC7: 2768 | AD7: 168 | AE7: 165626
B8: January-March | C8: 62624 | D8: 45041 | E8: 33215 | F8: 13472 | G8: 13848 | H8: 4471 | I8: 2971 | J8: 76 | K8: 175718 | M8: 62357 | N8: 46178 | O8: 33544 | P8: 13433 | Q8: 14191 | R8: 4787 | S8: 3219 | T8: 92 | U8: 177801 | W8: 124981 | X8: 91219 | Y8: 66759 | Z8: 26905 | AA8: 28039 | AB8: 9258 | AC8: 6190 | AD8: 168 | AE8: 353519
A9: June quarter 2014 | B9: April | C9: 24423 | D9: 16309 | E9: 14892 | F9: 6300 | G9: 5351 | H9: 1593 | I9: 1164 | J9: 640 | K9: 70672 | M9: 24316 | N9: 16436 | O9: 14790 | P9: 6155 | Q9: 5410 | R9: 1581 | S9: 1223 | T9: 554 | U9: 70465 | W9: 48739 | X9: 32745 | Y9: 29682 | Z9: 12455 | AA9: 10761 | AB9: 3174 | AC9: 2387 | AD9: 1194 | AE9: 141137
B10: May | C10: 22503 | D10: 15065 | E10: 14506 | F10: 7145 | G10: 4848 | H10: 1444 | I10: 1087 | J10: 2040 | K10: 68638 | M10: 22390 | N10: 15172 | O10: 14352 | P10: 7025 | Q10: 4915 | R10: 1516 | S10: 1113 | T10: 1777 | U10: 68260 | W10: 44893 | X10: 30237 | Y10: 28858 | Z10: 14170 | AA10: 9763 | AB10: 2960 | AC10: 2200 | AD10: 3817 | AE10: 136898
B11: June | C11: 25554 | D11: 18860 | E11: 17700 | F11: 10290 | G11: 5916 | H11: 1745 | I11: 1224 | J11: 2481 | K11: 83770 | M11: 26121 | N11: 19248 | O11: 17551 | P11: 9823 | Q11: 5936 | R11: 1927 | S11: 1288 | T11: 2271 | U11: 84165 | W11: 51675 | X11: 38108 | Y11: 35251 | Z11: 20113 | AA11: 11852 | AB11: 3672 | AC11: 2512 | AD11: 4752 | AE11: 167935
B12: April-June | C12: 72480 | D12: 50234 | E12: 47098 | F12: 23735 | G12: 16115 | H12: 4782 | I12: 3475 | J12: 5161 | K12: 223080 | M12: 72827 | N12: 50856 | O12: 46693 | P12: 23003 | Q12: 16261 | R12: 5024 | S12: 3624 | T12: 4602 | U12: 222890 | W12: 145307 | X12: 101090 | Y12: 93791 | Z12: 46738 | AA12: 32376 | AB12: 9806 | AC12: 7099 | AD12: 9763 | AE12: 445970
A13: September quarter 2014 | B13: July | C13: 18175 | D13: 13473 | E13: 12156 | F13: 6437 | G13: 4313 | H13: 1277 | I13: 850 | J13: 475 | K13: 57156 | M13: 18259 | N13: 13879 | O13: 12080 | P13: 6410 | Q13: 4301 | R13: 1334 | S13: 832 | T13: 436 | U13: 57531 | W13: 36434 | X13: 27352 | Y13: 24236 | Z13: 12847 | AA13: 8614 | AB13: 2611 | AC13: 1682 | AD13: 911 | AE13: 114687
B14: August | C14: 19728 | D14: 14674 | E14: 12971 | F14: 6960 | G14: 4510 | H14: 1395 | I14: 833 | J14: 108 | K14: 61179 | M14: 20536 | N14: 15077 | O14: 13082 | P14: 6671 | Q14: 4597 | R14: 1503 | S14: 862 | T14: 123 | U14: 62451 | W14: 40264 | X14: 29751 | Y14: 26053 | Z14: 13631 | AA14: 9107 | AB14: 2898 | AC14: 1695 | AD14: 231 | AE14: 123630
B15: September | C15: 15173 | D15: 11646 | E15: 9710 | F15: 4222 | G15: 4134 | H15: 1236 | I15: 764 | J15: 39 | K15: 46924 | M15: 15469 | N15: 11844 | O15: 10072 | P15: 4181 | Q15: 4290 | R15: 1351 | S15: 705 | T15: 55 | U15: 47967 | W15: 30642 | X15: 23490 | Y15: 19782 | Z15: 8403 | AA15: 8424 | AB15: 2587 | AC15: 1469 | AD15: 94 | AE15: 94891
